<?xml version="1.0"?>
<robot name="arm" xmlns:xacro="http://www.ros.org/wiki/xacro">

    <!-- Common Parameters -->
    <xacro:property name="base_length" value="0.1" />
    <xacro:property name="length" value="0.6" />
    <xacro:property name="radius" value="0.05" />
    <xacro:property name="lower_limit" value="-1.573" />
    <xacro:property name="upper_limit" value="0.0" />
    <xacro:property name="mass" value="1.0" />
    <xacro:property name="effort" value="1.0" />
    <xacro:property name="velocity" value="1.0" />

    <!-- Material Definitions -->
    <xacro:macro name="material" params="name color">
        <material name="${name}">
            <color rgba="${color}" />
        </material>
    </xacro:macro>

    <xacro:material name="red" color="1.0 0.0 0.0 1.0" />
    <xacro:material name="yellow" color="1.0 1.0 0.0 1.0" />

    <!-- Base -->
    <link name="robot_footprint" />

    <link name="base">
        <inertial>
            <origin xyz="0.0 0.0 0.0" rpy="0.0 0.0 0.0" />
            <mass value="1.0" />
            <inertia ixx="0.02147" ixy="0.0" ixz="0.0" iyy="0.02147" iyz="0.0" izz="0.04167" />
        </inertial>
        <visual>
            <origin xyz="0.0 0.0 0.0" rpy="0.0 0.0 0.0" />
            <geometry>
                <box size="0.50 0.50 0.20" />
            </geometry>
            <material name="yellow" />
        </visual>
        <collision>
            <origin xyz="0.0 0.0 0.0" rpy="0.0 0.0 0.0" />
            <geometry>
                <box size="0.50 0.50 0.20" />
            </geometry>
        </collision>
    </link>

    <joint name="robot_footprint_base" type="fixed">
        <origin xyz="0.0 0.0 0.1" rpy="0.0 0.0 0.0" />
        <parent link="robot_footprint" />
        <child link="base" />
    </joint>

    <!-- Base Link -->
    <link name="base_link">
        <visual>
            <geometry>
                <cylinder radius="${radius}" length="${base_length}" />
            </geometry>
            <origin xyz="0.0 0.0 0.0" rpy="0.0 0.0 0.0" />
        </visual>
        <collision>
            <geometry>
                <cylinder radius="${radius}" length="${base_length}" />
            </geometry>
            <origin xyz="0.0 0.0 0.0" rpy="0.0 0.0 0.0" />
        </collision>
    </link>

    <joint name="base_to_base_link" type="continuous">
        <parent link="base" />
        <child link="base_link" />
        <origin xyz="0 0 0.15" rpy="0 0 0" />
        <axis xyz="0.0 0.0 1.0" />
    </joint>

    <!-- Extension Macro -->
    <xacro:macro name="extension" params="parent child material extended_length">
        <link name="${child}">
            <inertial>
                <origin xyz="0.0 0.0 0.0" rpy="0.0 0.0 0.0" />
                <mass value="${mass}" />
                <inertia ixx="0.1" ixy="0.0" ixz="0.0" iyy="0.1" iyz="0.0" izz="0.1" />
            </inertial>
            <visual>
                <origin xyz="0.0 0.0 0.25" rpy="0.0 0.0 0.0" />
                <geometry>
                    <cylinder radius="${radius}" length="${length}" />
                </geometry>
                <material name="${material}" />
            </visual>
            <collision>
                <origin xyz="0.45 0.0 0.0" rpy="0.0 0.0 0.0" />
                <geometry>
                    <cylinder radius="${radius}" length="${length}" />
                </geometry>
            </collision>
        </link>

        <joint name="${parent}_to_${child}_joint" type="revolute">
            <origin xyz="0.0 0.0 ${extended_length}" rpy="0.0 0.0 0.0" />
            <parent link="${parent}" />
            <child link="${child}" />
            <axis xyz="0.0 1.0 0.0" />
            <limit lower="${lower_limit}" upper="${upper_limit}" effort="${effort}"
                velocity="${velocity}" />
        </joint>
    </xacro:macro>

    <!-- Robot Arm Links and Joints -->
    <xacro:extension child="shoulder" parent="base_link" material="yellow"
        extended_length="${base_length}" />
    <xacro:extension child="elbow" parent="shoulder" material="red" extended_length="${length}" />

    <!-- Wrist -->
    <link name="wrist">
        <inertial>
            <origin xyz="0.0 0.0 0.0" rpy="0.0 0.0 0.0" />
            <mass value="0.5" />
            <inertia ixx="0.0" ixy="0.0" ixz="0.0" iyy="0.0" iyz="0.0" izz="0.0" />
        </inertial>
        <visual>
            <origin xyz="0.0 0.0 0.0" rpy="0.0 0.0 0.0" />
            <geometry>
                <cylinder radius="${radius}" length="0.05" />
            </geometry>
            <material name="yellow" />
        </visual>
        <collision>
            <origin xyz="0.0 0.0 0.0" rpy="0.0 0.0 0.0" />
            <geometry>
                <box size="0.05 0.05 0.05" />
            </geometry>
        </collision>
    </link>

    <joint name="wrist_to_elbow" type="revolute">
        <origin xyz="0.0 0.0 ${length}" rpy="0.0 0.0 0.0" />
        <parent link="elbow" />
        <child link="wrist" />
        <axis xyz="0.0 0.0 1.0" />
        <limit lower="-1.573" upper="1.573" effort="1.0" velocity="0.01" />
    </joint>

</robot>